Workbook

Sheet README
A1: 🧾 Project Overview
A3: Lake of the Ozarks Property Intelligence Model
A5: This dataset identifies and ranks high-value waterfront properties using a scoring model based on property value, size, and water access.
A9: 🎯 Objective
A11: To create a targeting dataset for:
A13: Dock service companies
A14: Marine businesses
A15: Real estate professionals
A19: ⚙️ Methodology
A21: Combined active listings and recently sold properties
A22: Engineered features:
A23: dock_score
... A34: Summary metrics for decision-making

Sheet Dashboard
B1: Lake of the Ozarks Property Intelligence Dashboard
B2: Identifying high-value waterfront properties for targeted dock service opportunities | AA2: Segment
B4: Total Properties: | C4: =COUNTIF(lake_ozarks_homeowners_v1!N:N,"<>")-1 -> 58 | AA4: Premier Dock Owner | AB4: =COUNTIF(lake_ozarks_homeowners_v1!O:O,"Premier Dock Owner") -> 9
B5: Premier Dock Owners: | C5: =COUNTIF(lake_ozarks_homeowners_v1!O:O,"Premier Dock Owner") -> 9 | AA5: High-Value Dock Owner | AB5: =COUNTIF(lake_ozarks_homeowners_v1!O:O,"High-Value Dock Owner") -> 23
B6: High-Value Dock Owners: | C6: =COUNTIF(lake_ozarks_homeowners_v1!O:O,"High-Value Dock Owner") -> 23 | AA6: Waterfront / Access Prospect | AB6: =COUNTIF(lake_ozarks_homeowners_v1!O:O,"Waterfront / Access Prospect") -> 26
B7: Waterfront/Access Prospects: | C7: =COUNTIF(lake_ozarks_homeowners_v1!O:O,"Waterfront / Access Prospect") -> 26
B9: Active Listings: | C9: =COUNTIF(lake_ozarks_homeowners_v1!R:R,"*Active*") -> 29
B10: Recently Sold: | C10: =COUNTIF(lake_ozarks_homeowners_v1!R:R,"*Sold*") -> 29
B12: Priority A Targets: | C12: =COUNTIF(lake_ozarks_homeowners_v1!P:P,"A") -> 9
B13: Priority B Targets: | C13: =COUNTIF(lake_ozarks_homeowners_v1!P:P,"B") -> 23
B14: Priority C Targets: | C14: =COUNTIF(lake_ozarks_homeowners_v1!P:P,"C") -> 26
P15: `
B19: Top 10 High-Value Dock Ownership Targets
B20: Address | C20: City | D20: Property Value | E20: Dock Score | F20: Segment
B21: 282 Timber Ridge Ln | C21: Lake Ozark | D21: 6895500 | E21: 105 | F21: =IF(D21>=100,"Premier Dock Owner",IF(D21>=85,"High-Value Dock Owner",IF(D21>=65,"Waterfront / Access Prospect","Lower Priority"))) -> Premier Dock Owner
B22: LOT 10 Shootout Dr | C22: Osage Beach | D22: 6990000 | E22: 105 | F22: =IF(D22>=100,"Premier Dock Owner",IF(D22>=85,"High-Value Dock Owner",IF(D22>=65,"Waterfront / Access Prospect","Lower Priority"))) -> Premier Dock Owner
B23: 4650 Windsor Dr | C23: Osage Beach | D23: 6000000 | E23: 105 | F23: =IF(D23>=100,"Premier Dock Owner",IF(D23>=85,"High-Value Dock Owner",IF(D23>=65,"Waterfront / Access Prospect","Lower Priority"))) -> Premier Dock Owner
B24: LOT 2A Casas Del Ln | C24: Osage Beach | D24: 6699000 | E24: 105 | F24: =IF(D24>=100,"Premier Dock Owner",IF(D24>=85,"High-Value Dock Owner",IF(D24>=65,"Waterfront / Access Prospect","Lower Priority"))) -> Premier Dock Owner
B25: 5211 Dude Ranch Rd | C25: Osage Beach | D25: 5950000 | E25: 105 | F25: =IF(D25>=100,"Premier Dock Owner",IF(D25>=85,"High-Value Dock Owner",IF(D25>=65,"Waterfront / Access Prospect","Lower Priority"))) -> Premier Dock Owner
B26: 808 Las Campanas | C26: Sunrise Beach | D26: 4153300 | E26: 100 | F26: =IF(D26>=100,"Premier Dock Owner",IF(D26>=85,"High-Value Dock Owner",IF(D26>=65,"Waterfront / Access Prospect","Lower Priority"))) -> Premier Dock Owner
B27: 53 Rosco Rd | C27: Lake Ozark | D27: 3695000 | E27: 100 | F27: =IF(D27>=100,"Premier Dock Owner",IF(D27>=85,"High-Value Dock Owner",IF(D27>=65,"Waterfront / Access Prospect","Lower Priority"))) -> Premier Dock Owner
B28: 33 Vista Ct | C28: Sunset Beach | D28: 8954000 | E28: 100 | F28: =IF(D28>=100,"Premier Dock Owner",IF(D28>=85,"High-Value Dock Owner",IF(D28>=65,"Waterfront / Access Prospect","Lower Priority"))) -> Premier Dock Owner
B29: 1294 Squire Ln | C29: Osage Beach | D29: 4950000 | E29: 100 | F29: =IF(D29>=100,"Premier Dock Owner",IF(D29>=85,"High-Value Dock Owner",IF(D29>=65,"Waterfront / Access Prospect","Lower Priority"))) -> Premier Dock Owner
B30: 924 Las Campanas | C30: Sunrise Beach | D30: 2043600 | E30: 95 | F30: =IF(D30>=100,"Premier Dock Owner",IF(D30>=85,"High-Value Dock Owner",IF(D30>=65,"Waterfront / Access Prospect","Lower Priority"))) -> Premier Dock Owner
B32: Most properties fall into mid-to-high value dock ownership tiers, indicating strong targeting potential for marine service providers.
B35: Action Summary
B36: Immediate Outreach Targets (A): | D36: =C12 -> 9
B37: Secondary Outreach Targets (B): | D37: =C13 -> 23
B38: Low Priority / Monitor (C): | D38: =C14 -> 26
B40: Recommended Focus:
B41: Prioritize direct outreach to A-tier properties, followed by personalized campaigns for B-tier prospects.

Sheet lake_ozarks_homeowners_v1
A1: Lake of the Ozarks Property Intelligence Dataset
A3: Total Properties: | B3: =COUNTIF(N:N,"<>")-1 -> 58
A4: Premier Dock Owners: | B4: =COUNTIF(O:O,"Premier Dock Owner") -> 9
A5: High-Value Dock Owners: | B5: =COUNTIF(O:O,"High-Value Dock Owner") -> 23
A6: Waterfront Type | B6: =COUNTIF(O:O,"Waterfront / Access Prospect") -> 26
A8: Active Listings: | B8: =COUNTIF(R:R,"*Active*") -> 29
A9: Recently Sold: | B9: =COUNTIF(R:R,"*Sold*") -> 29
A10: standard_property_address | B10: lot_based_property_address | C10: property_city | D10: property_state | E10: property_zip | F10: beds | G10: baths | H10: sqft | I10: property_value | J10: price_per_sqft | K10: value_source | L10: waterfront_type | M10: dock_score | N10: rank | O10: segment | P10: target_priority | Q10: targeting_strategy | R10: data_type
A11: 282 Timber Ridge Ln | C11: Lake Ozark | D11: MO | E11: 65049 | F11: 6 | G11: 8 | H11: 6811 | I11: 6895500 | J11: =Table13[[#This Row],[property_value]]/Table13[[#This Row],[sqft]] -> 1012.4064 | K11: zestimate | L11: Dock | M11: =IF(L11="Dock",50,IF(L11="Waterfront",40,IF(L11="Access",20,0)))+IF(I11>5000000,30,IF(I11>2000000,25,IF(I11>1000000,20,10)))+IF(H11>6000,15,IF(H11>4000,10,5))+IF(F11>=6,10,IF(F11>=4,5,0)) -> 105 | N11: =_xlfn.RANK.EQ(M11,$M$11:$M$68,0) -> 1 | O11: =IF(M11>=100,"Premier Dock Owner",IF(M11>=85,"High-Value Dock Owner",IF(M11>=65,"Waterfront / Access Prospect","Lower Priority"))) -> Premier Dock Owner | P11: =IF(O11="Premier Dock Owner","A",IF(O11="High-Value Dock Owner","B","C")) -> A | Q11: =IF(Table13[[#This Row],[target_priority]]="A","Direct Outreach",IF(Table13[[#This Row],[target_priority]]="B","Personalized Mail Campaign","Low Priority / Monitor")) -> Direct Outreach | R11: Recently Sold
B12: LOT 10 Shootout Dr | C12: Osage Beach | D12: MO | E12: 65065 | F12: 8 | G12: 10 | H12: 8297 | I12: 6990000 | J12: =Table13[[#This Row],[property_value]]/Table13[[#This Row],[sqft]] -> 842.47318 | L12: Dock | M12: =IF(L12="Dock",50,IF(L12="Waterfront",40,IF(L12="Access",20,0)))+IF(I12>5000000,30,IF(I12>2000000,25,IF(I12>1000000,20,10)))+IF(H12>6000,15,IF(H12>4000,10,5))+IF(F12>=6,10,IF(F12>=4,5,0)) -> 105 | N12: =_xlfn.RANK.EQ(M12,$M$11:$M$68,0) -> 1 | O12: =IF(M12>=100,"Premier Dock Owner",IF(M12>=85,"High-Value Dock Owner",IF(M12>=65,"Waterfront / Access Prospect","Lower Priority"))) -> Premier Dock Owner | P12: =IF(O12="Premier Dock Owner","A",IF(O12="High-Value Dock Owner","B","C")) -> A | Q12: =IF(Table13[[#This Row],[target_priority]]="A","Direct Outreach",IF(Table13[[#This Row],[target_priority]]="B","Personalized Mail Campaign","Low Priority / Monitor")) -> Direct Outreach | R12: Active Listing
A13: 4650 Windsor Dr | C13: Osage Beach | D13: MO | E13: 65065 | F13: 6 | G13: 8 | H13: 7500 | I13: 6000000 | J13: =Table13[[#This Row],[property_value]]/Table13[[#This Row],[sqft]] -> 800 | L13: Dock | M13: =IF(L13="Dock",50,IF(L13="Waterfront",40,IF(L13="Access",20,0)))+IF(I13>5000000,30,IF(I13>2000000,25,IF(I13>1000000,20,10)))+IF(H13>6000,15,IF(H13>4000,10,5))+IF(F13>=6,10,IF(F13>=4,5,0)) -> 105 | N13: =_xlfn.RANK.EQ(M13,$M$11:$M$68,0) -> 1 | O13: =IF(M13>=100,"Premier Dock Owner",IF(M13>=85,"High-Value Dock Owner",IF(M13>=65,"Waterfront / Access Prospect","Lower Priority"))) -> Premier Dock Owner | P13: =IF(O13="Premier Dock Owner","A",IF(O13="High-Value Dock Owner","B","C")) -> A | Q13: =IF(Table13[[#This Row],[target_priority]]="A","Direct Outreach",IF(Table13[[#This Row],[target_priority]]="B","Personalized Mail Campaign","Low Priority / Monitor")) -> Direct Outreach | R13: Active Listing
B14: LOT 2A Casas Del Ln | C14: Osage Beach | D14: MO | E14: 65065 | F14: 6 | G14: 9 | H14: 10030 | I14: 6699000 | J14: =Table13[[#This Row],[property_value]]/Table13[[#This Row],[sqft]] -> 667.89631 | L14: Dock | M14: =IF(L14="Dock",50,IF(L14="Waterfront",40,IF(L14="Access",20,0)))+IF(I14>5000000,30,IF(I14>2000000,25,IF(I14>1000000,20,10)))+IF(H14>6000,15,IF(H14>4000,10,5))+IF(F14>=6,10,IF(F14>=4,5,0)) -> 105 | N14: =_xlfn.RANK.EQ(M14,$M$11:$M$68,0) -> 1 | O14: =IF(M14>=100,"Premier Dock Owner",IF(M14>=85,"High-Value Dock Owner",IF(M14>=65,"Waterfront / Access Prospect","Lower Priority"))) -> Premier Dock Owner | P14: =IF(O14="Premier Dock Owner","A",IF(O14="High-Value Dock Owner","B","C")) -> A | Q14: =IF(Table13[[#This Row],[target_priority]]="A","Direct Outreach",IF(Table13[[#This Row],[target_priority]]="B","Personalized Mail Campaign","Low Priority / Monitor")) -> Direct Outreach | R14: Active Listing
A15: 5211 Dude Ranch Rd | C15: Osage Beach | D15: MO | E15: 65065 | F15: 7 | G15: 7 | H15: 9800 | I15: 5950000 | J15: =Table13[[#This Row],[property_value]]/Table13[[#This Row],[sqft]] -> 607.14286 | L15: Dock | M15: =IF(L15="Dock",50,IF(L15="Waterfront",40,IF(L15="Access",20,0)))+IF(I15>5000000,30,IF(I15>2000000,25,IF(I15>1000000,20,10)))+IF(H15>6000,15,IF(H15>4000,10,5))+IF(F15>=6,10,IF(F15>=4,5,0)) -> 105 | N15: =_xlfn.RANK.EQ(M15,$M$11:$M$68,0) -> 1 | O15: =IF(M15>=100,"Premier Dock Owner",IF(M15>=85,"High-Value Dock Owner",IF(M15>=65,"Waterfront / Access Prospect","Lower Priority"))) -> Premier Dock Owner | P15: =IF(O15="Premier Dock Owner","A",IF(O15="High-Value Dock Owner","B","C")) -> A | Q15: =IF(Table13[[#This Row],[target_priority]]="A","Direct Outreach",IF(Table13[[#This Row],[target_priority]]="B","Personalized Mail Campaign","Low Priority / Monitor")) -> Direct Outreach | R15: Active Listing
A16: 808 Las Campanas | C16: Sunrise Beach | D16: MO | E16: 65079 | F16: 7 | G16: 9 | H16: 8067 | I16: 4153300 | J16: =Table13[[#This Row],[property_value]]/Table13[[#This Row],[sqft]] -> 514.85063 | K16: zestimate | L16: Dock | M16: =IF(L16="Dock",50,IF(L16="Waterfront",40,IF(L16="Access",20,0)))+IF(I16>5000000,30,IF(I16>2000000,25,IF(I16>1000000,20,10)))+IF(H16>6000,15,IF(H16>4000,10,5))+IF(F16>=6,10,IF(F16>=4,5,0)) -> 100 | N16: =_xlfn.RANK.EQ(M16,$M$11:$M$68,0) -> 6 | O16: =IF(M16>=100,"Premier Dock Owner",IF(M16>=85,"High-Value Dock Owner",IF(M16>=65,"Waterfront / Access Prospect","Lower Priority"))) -> Premier Dock Owner | P16: =IF(O16="Premier Dock Owner","A",IF(O16="High-Value Dock Owner","B","C")) -> A | Q16: =IF(Table13[[#This Row],[target_priority]]="A","Direct Outreach",IF(Table13[[#This Row],[target_priority]]="B","Personalized Mail Campaign","Low Priority / Monitor")) -> Direct Outreach | R16: Recently Sold
A17: 53 Rosco Rd | C17: Lake Ozark | D17: MO | E17: 65049 | F17: 8 | G17: 7 | H17: 6058 | I17: 3695000 | J17: =Table13[[#This Row],[property_value]]/Table13[[#This Row],[sqft]] -> 609.93727 | L17: Dock | M17: =IF(L17="Dock",50,IF(L17="Waterfront",40,IF(L17="Access",20,0)))+IF(I17>5000000,30,IF(I17>2000000,25,IF(I17>1000000,20,10)))+IF(H17>6000,15,IF(H17>4000,10,5))+IF(F17>=6,10,IF(F17>=4,5,0)) -> 100 | N17: =_xlfn.RANK.EQ(M17,$M$11:$M$68,0) -> 6 | O17: =IF(M17>=100,"Premier Dock Owner",IF(M17>=85,"High-Value Dock Owner",IF(M17>=65,"Waterfront / Access Prospect","Lower Priority"))) -> Premier Dock Owner | P17: =IF(O17="Premier Dock Owner","A",IF(O17="High-Value Dock Owner","B","C")) -> A | Q17: =IF(Table13[[#This Row],[target_priority]]="A","Direct Outreach",IF(Table13[[#This Row],[target_priority]]="B","Personalized Mail Campaign","Low Priority / Monitor")) -> Direct Outreach | R17: Active Listing
A18: 33 Vista Ct | C18: Sunset Beach | D18: MO | E18: 65079 | F18: 5 | G18: 6 | H18: 10300 | I18: 8954000 | J18: =Table13[[#This Row],[property_value]]/Table13[[#This Row],[sqft]] -> 869.32039 | L18: Dock | M18: =IF(L18="Dock",50,IF(L18="Waterfront",40,IF(L18="Access",20,0)))+IF(I18>5000000,30,IF(I18>2000000,25,IF(I18>1000000,20,10)))+IF(H18>6000,15,IF(H18>4000,10,5))+IF(F18>=6,10,IF(F18>=4,5,0)) -> 100 | N18: =_xlfn.RANK.EQ(M18,$M$11:$M$68,0) -> 6 | O18: =IF(M18>=100,"Premier Dock Owner",IF(M18>=85,"High-Value Dock Owner",IF(M18>=65,"Waterfront / Access Prospect","Lower Priority"))) -> Premier Dock Owner | P18: =IF(O18="Premier Dock Owner","A",IF(O18="High-Value Dock Owner","B","C")) -> A | Q18: =IF(Table13[[#This Row],[target_priority]]="A","Direct Outreach",IF(Table13[[#This Row],[target_priority]]="B","Personalized Mail Campaign","Low Priority / Monitor")) -> Direct Outreach | R18: Active Listing
A19: 1294 Squire Ln | C19: Osage Beach | D19: MO | E19: 65065 | F19: 6 | G19: 7 | H19: 7315 | I19: 4950000 | J19: =Table13[[#This Row],[property_value]]/Table13[[#This Row],[sqft]] -> 676.69173 | L19: Dock | M19: =IF(L19="Dock",50,IF(L19="Waterfront",40,IF(L19="Access",20,0)))+IF(I19>5000000,30,IF(I19>2000000,25,IF(I19>1000000,20,10)))+IF(H19>6000,15,IF(H19>4000,10,5))+IF(F19>=6,10,IF(F19>=4,5,0)) -> 100 | N19: =_xlfn.RANK.EQ(M19,$M$11:$M$68,0) -> 6 | O19: =IF(M19>=100,"Premier Dock Owner",IF(M19>=85,"High-Value Dock Owner",IF(M19>=65,"Waterfront / Access Prospect","Lower Priority"))) -> Premier Dock Owner | P19: =IF(O19="Premier Dock Owner","A",IF(O19="High-Value Dock Owner","B","C")) -> A | Q19: =IF(Table13[[#This Row],[target_priority]]="A","Direct Outreach",IF(Table13[[#This Row],[target_priority]]="B","Personalized Mail Campaign","Low Priority / Monitor")) -> Direct Outreach | R19: Active Listing
A20: 924 Las Campanas | C20: Sunrise Beach | D20: MO | E20: 65079 | F20: 6 | G20: 5 | H20: 4334 | I20: 2043600 | J20: =Table13[[#This Row],[property_value]]/Table13[[#This Row],[sqft]] -> 471.52746 | K20: zestimate | L20: Dock | M20: =IF(L20="Dock",50,IF(L20="Waterfront",40,IF(L20="Access",20,0)))+IF(I20>5000000,30,IF(I20>2000000,25,IF(I20>1000000,20,10)))+IF(H20>6000,15,IF(H20>4000,10,5))+IF(F20>=6,10,IF(F20>=4,5,0)) -> 95 | N20: =_xlfn.RANK.EQ(M20,$M$11:$M$68,0) -> 10 | O20: =IF(M20>=100,"Premier Dock Owner",IF(M20>=85,"High-Value Dock Owner",IF(M20>=65,"Waterfront / Access Prospect","Lower Priority"))) -> High-Value Dock Owner | P20: =IF(O20="Premier Dock Owner","A",IF(O20="High-Value Dock Owner","B","C")) -> B | Q20: =IF(Table13[[#This Row],[target_priority]]="A","Direct Outreach",IF(Table13[[#This Row],[target_priority]]="B","Personalized Mail Campaign","Low Priority / Monitor")) -> Personalized Mail Campaign | R20: Recently Sold
A21: 300 Beachnut Dr | C21: Sunset Beach | D21: MO | E21: 65079 | F21: 5 | G21: 5 | H21: 5431 | I21: 5500000 | J21: =Table13[[#This Row],[property_value]]/Table13[[#This Row],[sqft]] -> 1012.7048 | L21: Dock | M21: =IF(L21="Dock",50,IF(L21="Waterfront",40,IF(L21="Access",20,0)))+IF(I21>5000000,30,IF(I21>2000000,25,IF(I21>1000000,20,10)))+IF(H21>6000,15,IF(H21>4000,10,5))+IF(F21>=6,10,IF(F21>=4,5,0)) -> 95 | N21: =_xlfn.RANK.EQ(M21,$M$11:$M$68,0) -> 10 | O21: =IF(M21>=100,"Premier Dock Owner",IF(M21>=85,"High-Value Dock Owner",IF(M21>=65,"Waterfront / Access Prospect","Lower Priority"))) -> High-Value Dock Owner | P21: =IF(O21="Premier Dock Owner","A",IF(O21="High-Value Dock Owner","B","C")) -> B | Q21: =IF(Table13[[#This Row],[target_priority]]="A","Direct Outreach",IF(Table13[[#This Row],[target_priority]]="B","Personalized Mail Campaign","Low Priority / Monitor")) -> Personalized Mail Campaign | R21: Active Listing
A22: 205 Beachnut Dr | C22: Sunset Beach | D22: MO | E22: 65079 | F22: 6 | G22: 6 | H22: 4834 | I22: 2490000 | J22: =Table13[[#This Row],[property_value]]/Table13[[#This Row],[sqft]] -> 515.10137 | L22: Dock | M22: =IF(L22="Dock",50,IF(L22="Waterfront",40,IF(L22="Access",20,0)))+IF(I22>5000000,30,IF(I22>2000000,25,IF(I22>1000000,20,10)))+IF(H22>6000,15,IF(H22>4000,10,5))+IF(F22>=6,10,IF(F22>=4,5,0)) -> 95 | N22: =_xlfn.RANK.EQ(M22,$M$11:$M$68,0) -> 10 | O22: =IF(M22>=100,"Premier Dock Owner",IF(M22>=85,"High-Value Dock Owner",IF(M22>=65,"Waterfront / Access Prospect","Lower Priority"))) -> High-Value Dock Owner | P22: =IF(O22="Premier Dock Owner","A",IF(O22="High-Value Dock Owner","B","C")) -> B | Q22: =IF(Table13[[#This Row],[target_priority]]="A","Direct Outreach",IF(Table13[[#This Row],[target_priority]]="B","Personalized Mail Campaign","Low Priority / Monitor")) -> Personalized Mail Campaign | R22: Active Listing
A23: 1254 Darwin Dr | C23: Osage Beach | D23: MO | E23: 65065 | F23: 4 | G23: 5 | H23: 6600 | I23: 2250000 | J23: =Table13[[#This Row],[property_value]]/Table13[[#This Row],[sqft]] -> 340.90909 | L23: Dock | M23: =IF(L23="Dock",50,IF(L23="Waterfront",40,IF(L23="Access",20,0)))+IF(I23>5000000,30,IF(I23>2000000,25,IF(I23>1000000,20,10)))+IF(H23>6000,15,IF(H23>4000,10,5))+IF(F23>=6,10,IF(F23>=4,5,0)) -> 95 | N23: =_xlfn.RANK.EQ(M23,$M$11:$M$68,0) -> 10 | O23: =IF(M23>=100,"Premier Dock Owner",IF(M23>=85,"High-Value Dock Owner",IF(M23>=65,"Waterfront / Access Prospect","Lower Priority"))) -> High-Value Dock Owner | P23: =IF(O23="Premier Dock Owner","A",IF(O23="High-Value Dock Owner","B","C")) -> B | Q23: =IF(Table13[[#This Row],[target_priority]]="A","Direct Outreach",IF(Table13[[#This Row],[target_priority]]="B","Personalized Mail Campaign","Low Priority / Monitor")) -> Personalized Mail Campaign | R23: Active Listing
A24: 29 Forest Trce | C24: Villages | D24: MO | E24: 65079 | F24: 6 | G24: 6 | H24: 5300 | I24: 3450000 | J24: =Table13[[#This Row],[property_value]]/Table13[[#This Row],[sqft]] -> 650.9434 | L24: Dock | M24: =IF(L24="Dock",50,IF(L24="Waterfront",40,IF(L24="Access",20,0)))+IF(I24>5000000,30,IF(I24>2000000,25,IF(I24>1000000,20,10)))+IF(H24>6000,15,IF(H24>4000,10,5))+IF(F24>=6,10,IF(F24>=4,5,0)) -> 95 | N24: =_xlfn.RANK.EQ(M24,$M$11:$M$68,0) -> 10 | O24: =IF(M24>=100,"Premier Dock Owner",IF(M24>=85,"High-Value Dock Owner",IF(M24>=65,"Waterfront / Access Prospect","Lower Priority"))) -> High-Value Dock Owner | P24: =IF(O24="Premier Dock Owner","A",IF(O24="High-Value Dock Owner","B","C")) -> B | Q24: =IF(Table13[[#This Row],[target_priority]]="A","Direct Outreach",IF(Table13[[#This Row],[target_priority]]="B","Personalized Mail Campaign","Low Priority / Monitor")) -> Personalized Mail Campaign | R24: Active Listing
A25: 1114 Grand Cove Rd | C25: Sunrise Beach | D25: MO | E25: 65079 | F25: 4 | G25: 5 | H25: 5710 | I25: 3271600 | J25: =Table13[[#This Row],[property_value]]/Table13[[#This Row],[sqft]] -> 572.95972 | K25: zestimate | L25: Dock | M25: =IF(L25="Dock",50,IF(L25="Waterfront",40,IF(L25="Access",20,0)))+IF(I25>5000000,30,IF(I25>2000000,25,IF(I25>1000000,20,10)))+IF(H25>6000,15,IF(H25>4000,10,5))+IF(F25>=6,10,IF(F25>=4,5,0)) -> 90 | N25: =_xlfn.RANK.EQ(M25,$M$11:$M$68,0) -> 15 | O25: =IF(M25>=100,"Premier Dock Owner",IF(M25>=85,"High-Value Dock Owner",IF(M25>=65,"Waterfront / Access Prospect","Lower Priority"))) -> High-Value Dock Owner | P25: =IF(O25="Premier Dock Owner","A",IF(O25="High-Value Dock Owner","B","C")) -> B | Q25: =IF(Table13[[#This Row],[target_priority]]="A","Direct Outreach",IF(Table13[[#This Row],[target_priority]]="B","Personalized Mail Campaign","Low Priority / Monitor")) -> Personalized Mail Campaign | R25: Recently Sold
A26: 377 Lake Dr | C26: Sunrise Beach | D26: MO | E26: 65079 | F26: 4 | G26: 5 | H26: 5105 | I26: 2249900 | J26: =Table13[[#This Row],[property_value]]/Table13[[#This Row],[sqft]] -> 440.72478 | K26: estimated | L26: Dock | M26: =IF(L26="Dock",50,IF(L26="Waterfront",40,IF(L26="Access",20,0)))+IF(I26>5000000,30,IF(I26>2000000,25,IF(I26>1000000,20,10)))+IF(H26>6000,15,IF(H26>4000,10,5))+IF(F26>=6,10,IF(F26>=4,5,0)) -> 90 | N26: =_xlfn.RANK.EQ(M26,$M$11:$M$68,0) -> 15 | O26: =IF(M26>=100,"Premier Dock Owner",IF(M26>=85,"High-Value Dock Owner",IF(M26>=65,"Waterfront / Access Prospect","Lower Priority"))) -> High-Value Dock Owner | P26: =IF(O26="Premier Dock Owner","A",IF(O26="High-Value Dock Owner","B","C")) -> B | Q26: =IF(Table13[[#This Row],[target_priority]]="A","Direct Outreach",IF(Table13[[#This Row],[target_priority]]="B","Personalized Mail Campaign","Low Priority / Monitor")) -> Personalized Mail Campaign | R26: Recently Sold
A27: 36 Via Preminenta | C27: Sunrise Beach | D27: MO | E27: 65079 | F27: 6 | G27: 7 | H27: 4864 | I27: 1905500 | J27: =Table13[[#This Row],[property_value]]/Table13[[#This Row],[sqft]] -> 391.75576 | K27: zestimate | L27: Dock | M27: =IF(L27="Dock",50,IF(L27="Waterfront",40,IF(L27="Access",20,0)))+IF(I27>5000000,30,IF(I27>2000000,25,IF(I27>1000000,20,10)))+IF(H27>6000,15,IF(H27>4000,10,5))+IF(F27>=6,10,IF(F27>=4,5,0)) -> 90 | N27: =_xlfn.RANK.EQ(M27,$M$11:$M$68,0) -> 15 | O27: =IF(M27>=100,"Premier Dock Owner",IF(M27>=85,"High-Value Dock Owner",IF(M27>=65,"Waterfront / Access Prospect","Lower Priority"))) -> High-Value Dock Owner | P27: =IF(O27="Premier Dock Owner","A",IF(O27="High-Value Dock Owner","B","C")) -> B | Q27: =IF(Table13[[#This Row],[target_priority]]="A","Direct Outreach",IF(Table13[[#This Row],[target_priority]]="B","Personalized Mail Campaign","Low Priority / Monitor")) -> Personalized Mail Campaign | R27: Recently Sold
A28: 387 Lake Dr, | C28: Sunrise Beach | D28: MO | E28: 65079 | F28: 4 | G28: 5 | H28: 4415 | I28: 2014900 | J28: =Table13[[#This Row],[property_value]]/Table13[[#This Row],[sqft]] -> 456.37599 | K28: zestimate | L28: Dock | M28: =IF(L28="Dock",50,IF(L28="Waterfront",40,IF(L28="Access",20,0)))+IF(I28>5000000,30,IF(I28>2000000,25,IF(I28>1000000,20,10)))+IF(H28>6000,15,IF(H28>4000,10,5))+IF(F28>=6,10,IF(F28>=4,5,0)) -> 90 | N28: =_xlfn.RANK.EQ(M28,$M$11:$M$68,0) -> 15 | O28: =IF(M28>=100,"Premier Dock Owner",IF(M28>=85,"High-Value Dock Owner",IF(M28>=65,"Waterfront / Access Prospect","Lower Priority"))) -> High-Value Dock Owner | P28: =IF(O28="Premier Dock Owner","A",IF(O28="High-Value Dock Owner","B","C")) -> B | Q28: =IF(Table13[[#This Row],[target_priority]]="A","Direct Outreach",IF(Table13[[#This Row],[target_priority]]="B","Personalized Mail Campaign","Low Priority / Monitor")) -> Personalized Mail Campaign | R28: Recently Sold
A29: 439 Redbud Ct | C29: Lake Ozark | D29: MO | E29: 65049 | F29: 5 | G29: 6 | H29: 4200 | I29: 2485000 | J29: =Table13[[#This Row],[property_value]]/Table13[[#This Row],[sqft]] -> 591.66667 | L29: Dock | M29: =IF(L29="Dock",50,IF(L29="Waterfront",40,IF(L29="Access",20,0)))+IF(I29>5000000,30,IF(I29>2000000,25,IF(I29>1000000,20,10)))+IF(H29>6000,15,IF(H29>4000,10,5))+IF(F29>=6,10,IF(F29>=4,5,0)) -> 90 | N29: =_xlfn.RANK.EQ(M29,$M$11:$M$68,0) -> 15 | O29: =IF(M29>=100,"Premier Dock Owner",IF(M29>=85,"High-Value Dock Owner",IF(M29>=65,"Waterfront / Access Prospect","Lower Priority"))) -> High-Value Dock Owner | P29: =IF(O29="Premier Dock Owner","A",IF(O29="High-Value Dock Owner","B","C")) -> B | Q29: =IF(Table13[[#This Row],[target_priority]]="A","Direct Outreach",IF(Table13[[#This Row],[target_priority]]="B","Personalized Mail Campaign","Low Priority / Monitor")) -> Personalized Mail Campaign | R29: Active Listing
A30: 820 Cedar Crest Dr | C30: Lake Ozark | D30: MO | E30: 65049 | F30: 5 | G30: 6 | H30: 6340 | I30: 1950000 | J30: =Table13[[#This Row],[property_value]]/Table13[[#This Row],[sqft]] -> 307.57098 | L30: Dock | M30: =IF(L30="Dock",50,IF(L30="Waterfront",40,IF(L30="Access",20,0)))+IF(I30>5000000,30,IF(I30>2000000,25,IF(I30>1000000,20,10)))+IF(H30>6000,15,IF(H30>4000,10,5))+IF(F30>=6,10,IF(F30>=4,5,0)) -> 90 | N30: =_xlfn.RANK.EQ(M30,$M$11:$M$68,0) -> 15 | O30: =IF(M30>=100,"Premier Dock Owner",IF(M30>=85,"High-Value Dock Owner",IF(M30>=65,"Waterfront / Access Prospect","Lower Priority"))) -> High-Value Dock Owner | P30: =IF(O30="Premier Dock Owner","A",IF(O30="High-Value Dock Owner","B","C")) -> B | Q30: =IF(Table13[[#This Row],[target_priority]]="A","Direct Outreach",IF(Table13[[#This Row],[target_priority]]="B","Personalized Mail Campaign","Low Priority / Monitor")) -> Personalized Mail Campaign | R30: Active Listing
A31: 186 Frudeger Rd | C31: Lake Ozark | D31: MO | E31: 65049 | F31: 8 | G31: 7 | H31: 5800 | I31: 1995000 | J31: =Table13[[#This Row],[property_value]]/Table13[[#This Row],[sqft]] -> 343.96552 | L31: Dock | M31: =IF(L31="Dock",50,IF(L31="Waterfront",40,IF(L31="Access",20,0)))+IF(I31>5000000,30,IF(I31>2000000,25,IF(I31>1000000,20,10)))+IF(H31>6000,15,IF(H31>4000,10,5))+IF(F31>=6,10,IF(F31>=4,5,0)) -> 90 | N31: =_xlfn.RANK.EQ(M31,$M$11:$M$68,0) -> 15 | O31: =IF(M31>=100,"Premier Dock Owner",IF(M31>=85,"High-Value Dock Owner",IF(M31>=65,"Waterfront / Access Prospect","Lower Priority"))) -> High-Value Dock Owner | P31: =IF(O31="Premier Dock Owner","A",IF(O31="High-Value Dock Owner","B","C")) -> B | Q31: =IF(Table13[[#This Row],[target_priority]]="A","Direct Outreach",IF(Table13[[#This Row],[target_priority]]="B","Personalized Mail Campaign","Low Priority / Monitor")) -> Personalized Mail Campaign | R31: Active Listing
A32: 283 & 298 Tropical Trail Rd | C32: Sunset Beach | D32: MO | E32: 65079 | F32: 9 | G32: 11 | H32: 5742 | I32: 1839900 | J32: =Table13[[#This Row],[property_value]]/Table13[[#This Row],[sqft]] -> 320.42842 | L32: Dock | M32: =IF(L32="Dock",50,IF(L32="Waterfront",40,IF(L32="Access",20,0)))+IF(I32>5000000,30,IF(I32>2000000,25,IF(I32>1000000,20,10)))+IF(H32>6000,15,IF(H32>4000,10,5))+IF(F32>=6,10,IF(F32>=4,5,0)) -> 90 | N32: =_xlfn.RANK.EQ(M32,$M$11:$M$68,0) -> 15 | O32: =IF(M32>=100,"Premier Dock Owner",IF(M32>=85,"High-Value Dock Owner",IF(M32>=65,"Waterfront / Access Prospect","Lower Priority"))) -> High-Value Dock Owner | P32: =IF(O32="Premier Dock Owner","A",IF(O32="High-Value Dock Owner","B","C")) -> B | Q32: =IF(Table13[[#This Row],[target_priority]]="A","Direct Outreach",IF(Table13[[#This Row],[target_priority]]="B","Personalized Mail Campaign","Low Priority / Monitor")) -> Personalized Mail Campaign | R32: Active Listing
A33: 50 Brookhaven Ct | C33: Sunset Beach | D33: MO | E33: 65079 | F33: 5 | G33: 5 | H33: 4616 | I33: 2895000 | J33: =Table13[[#This Row],[property_value]]/Table13[[#This Row],[sqft]] -> 627.16638 | L33: Dock | M33: =IF(L33="Dock",50,IF(L33="Waterfront",40,IF(L33="Access",20,0)))+IF(I33>5000000,30,IF(I33>2000000,25,IF(I33>1000000,20,10)))+IF(H33>6000,15,IF(H33>4000,10,5))+IF(F33>=6,10,IF(F33>=4,5,0)) -> 90 | N33: =_xlfn.RANK.EQ(M33,$M$11:$M$68,0) -> 15 | O33: =IF(M33>=100,"Premier Dock Owner",IF(M33>=85,"High-Value Dock Owner",IF(M33>=65,"Waterfront / Access Prospect","Lower Priority"))) -> High-Value Dock Owner | P33: =IF(O33="Premier Dock Owner","A",IF(O33="High-Value Dock Owner","B","C")) -> B | Q33: =IF(Table13[[#This Row],[target_priority]]="A","Direct Outreach",IF(Table13[[#This Row],[target_priority]]="B","Personalized Mail Campaign","Low Priority / Monitor")) -> Personalized Mail Campaign | R33: Active Listing
A34: 374 Lakeshore Dr | C34: Lake Ozark | D34: MO | E34: 65049 | F34: 5 | G34: 5 | H34: 5000 | I34: 1694900 | J34: =Table13[[#This Row],[property_value]]/Table13[[#This Row],[sqft]] -> 338.98 | K34: zestimate | L34: Dock | M34: =IF(L34="Dock",50,IF(L34="Waterfront",40,IF(L34="Access",20,0)))+IF(I34>5000000,30,IF(I34>2000000,25,IF(I34>1000000,20,10)))+IF(H34>6000,15,IF(H34>4000,10,5))+IF(F34>=6,10,IF(F34>=4,5,0)) -> 85 | N34: =_xlfn.RANK.EQ(M34,$M$11:$M$68,0) -> 24 | O34: =IF(M34>=100,"Premier Dock Owner",IF(M34>=85,"High-Value Dock Owner",IF(M34>=65,"Waterfront / Access Prospect","Lower Priority"))) -> High-Value Dock Owner | P34: =IF(O34="Premier Dock Owner","A",IF(O34="High-Value Dock Owner","B","C")) -> B | Q34: =IF(Table13[[#This Row],[target_priority]]="A","Direct Outreach",IF(Table13[[#This Row],[target_priority]]="B","Personalized Mail Campaign","Low Priority / Monitor")) -> Personalized Mail Campaign | R34: Recently Sold
A35: 825 Grand View Dr | C35: Sunrise Beach | D35: MO | E35: 65079 | F35: 5 | G35: 5 | H35: 4746 | I35: 1149800 | J35: =Table13[[#This Row],[property_value]]/Table13[[#This Row],[sqft]] -> 242.26717 | K35: zestimate | L35: Dock | M35: =IF(L35="Dock",50,IF(L35="Waterfront",40,IF(L35="Access",20,0)))+IF(I35>5000000,30,IF(I35>2000000,25,IF(I35>1000000,20,10)))+IF(H35>6000,15,IF(H35>4000,10,5))+IF(F35>=6,10,IF(F35>=4,5,0)) -> 85 | N35: =_xlfn.RANK.EQ(M35,$M$11:$M$68,0) -> 24 | O35: =IF(M35>=100,"Premier Dock Owner",IF(M35>=85,"High-Value Dock Owner",IF(M35>=65,"Waterfront / Access Prospect","Lower Priority"))) -> High-Value Dock Owner | P35: =IF(O35="Premier Dock Owner","A",IF(O35="High-Value Dock Owner","B","C")) -> B | Q35: =IF(Table13[[#This Row],[target_priority]]="A","Direct Outreach",IF(Table13[[#This Row],[target_priority]]="B","Personalized Mail Campaign","Low Priority / Monitor")) -> Personalized Mail Campaign | R35: Recently Sold
A36: 853 Sweetwater Dr | C36: Four Seasons | D36: MO | E36: 65049 | F36: 5 | G36: 5 | H36: 5765 | I36: 1288900 | J36: =Table13[[#This Row],[property_value]]/Table13[[#This Row],[sqft]] -> 223.57329 | K36: zestimate | L36: Dock | M36: =IF(L36="Dock",50,IF(L36="Waterfront",40,IF(L36="Access",20,0)))+IF(I36>5000000,30,IF(I36>2000000,25,IF(I36>1000000,20,10)))+IF(H36>6000,15,IF(H36>4000,10,5))+IF(F36>=6,10,IF(F36>=4,5,0)) -> 85 | N36: =_xlfn.RANK.EQ(M36,$M$11:$M$68,0) -> 24 | O36: =IF(M36>=100,"Premier Dock Owner",IF(M36>=85,"High-Value Dock Owner",IF(M36>=65,"Waterfront / Access Prospect","Lower Priority"))) -> High-Value Dock Owner | P36: =IF(O36="Premier Dock Owner","A",IF(O36="High-Value Dock Owner","B","C")) -> B | Q36: =IF(Table13[[#This Row],[target_priority]]="A","Direct Outreach",IF(Table13[[#This Row],[target_priority]]="B","Personalized Mail Campaign","Low Priority / Monitor")) -> Personalized Mail Campaign | R36: Recently Sold
A37: 644 Twin Valley Loop | C37: Linn Creek | D37: MO | E37: 65052 | F37: 5 | G37: 4 | H37: 4400 | I37: 1059800 | J37: =Table13[[#This Row],[property_value]]/Table13[[#This Row],[sqft]] -> 240.86364 | K37: zestimate | L37: Dock | M37: =IF(L37="Dock",50,IF(L37="Waterfront",40,IF(L37="Access",20,0)))+IF(I37>5000000,30,IF(I37>2000000,25,IF(I37>1000000,20,10)))+IF(H37>6000,15,IF(H37>4000,10,5))+IF(F37>=6,10,IF(F37>=4,5,0)) -> 85 | N37: =_xlfn.RANK.EQ(M37,$M$11:$M$68,0) -> 24 | O37: =IF(M37>=100,"Premier Dock Owner",IF(M37>=85,"High-Value Dock Owner",IF(M37>=65,"Waterfront / Access Prospect","Lower Priority"))) -> High-Value Dock Owner | P37: =IF(O37="Premier Dock Owner","A",IF(O37="High-Value Dock Owner","B","C")) -> B | Q37: =IF(Table13[[#This Row],[target_priority]]="A","Direct Outreach",IF(Table13[[#This Row],[target_priority]]="B","Personalized Mail Campaign","Low Priority / Monitor")) -> Personalized Mail Campaign | R37: Recently Sold
A38: 25 Elm Ct | C38: Lake Ozark | D38: MO | E38: 65049 | F38: 5 | G38: 6 | H38: 4575 | I38: 1639800 | J38: =Table13[[#This Row],[property_value]]/Table13[[#This Row],[sqft]] -> 358.42623 | K38: zestimate | L38: Dock | M38: =IF(L38="Dock",50,IF(L38="Waterfront",40,IF(L38="Access",20,0)))+IF(I38>5000000,30,IF(I38>2000000,25,IF(I38>1000000,20,10)))+IF(H38>6000,15,IF(H38>4000,10,5))+IF(F38>=6,10,IF(F38>=4,5,0)) -> 85 | N38: =_xlfn.RANK.EQ(M38,$M$11:$M$68,0) -> 24 | O38: =IF(M38>=100,"Premier Dock Owner",IF(M38>=85,"High-Value Dock Owner",IF(M38>=65,"Waterfront / Access Prospect","Lower Priority"))) -> High-Value Dock Owner | P38: =IF(O38="Premier Dock Owner","A",IF(O38="High-Value Dock Owner","B","C")) -> B | Q38: =IF(Table13[[#This Row],[target_priority]]="A","Direct Outreach",IF(Table13[[#This Row],[target_priority]]="B","Personalized Mail Campaign","Low Priority / Monitor")) -> Personalized Mail Campaign | R38: Recently Sold
A39: 446 Sioux Rd | C39: Lake Ozark | D39: MO | E39: 65049 | F39: 4 | G39: 5 | H39: 4368 | I39: 1517500 | J39: =Table13[[#This Row],[property_value]]/Table13[[#This Row],[sqft]] -> 347.413 | K39: zestimate | L39: Dock | M39: =IF(L39="Dock",50,IF(L39="Waterfront",40,IF(L39="Access",20,0)))+IF(I39>5000000,30,IF(I39>2000000,25,IF(I39>1000000,20,10)))+IF(H39>6000,15,IF(H39>4000,10,5))+IF(F39>=6,10,IF(F39>=4,5,0)) -> 85 | N39: =_xlfn.RANK.EQ(M39,$M$11:$M$68,0) -> 24 | O39: =IF(M39>=100,"Premier Dock Owner",IF(M39>=85,"High-Value Dock Owner",IF(M39>=65,"Waterfront / Access Prospect","Lower Priority"))) -> High-Value Dock Owner | P39: =IF(O39="Premier Dock Owner","A",IF(O39="High-Value Dock Owner","B","C")) -> B | Q39: =IF(Table13[[#This Row],[target_priority]]="A","Direct Outreach",IF(Table13[[#This Row],[target_priority]]="B","Personalized Mail Campaign","Low Priority / Monitor")) -> Personalized Mail Campaign | R39: Recently Sold
A40: 853 Sweetwater Dr | C40: Four Seasons | D40: MO | E40: 65049 | F40: 5 | G40: 5 | H40: 5765 | I40: 1288900 | J40: =Table13[[#This Row],[property_value]]/Table13[[#This Row],[sqft]] -> 223.57329 | K40: zestimate | L40: Dock | M40: =IF(L40="Dock",50,IF(L40="Waterfront",40,IF(L40="Access",20,0)))+IF(I40>5000000,30,IF(I40>2000000,25,IF(I40>1000000,20,10)))+IF(H40>6000,15,IF(H40>4000,10,5))+IF(F40>=6,10,IF(F40>=4,5,0)) -> 85 | N40: =_xlfn.RANK.EQ(M40,$M$11:$M$68,0) -> 24 | O40: =IF(M40>=100,"Premier Dock Owner",IF(M40>=85,"High-Value Dock Owner",IF(M40>=65,"Waterfront / Access Prospect","Lower Priority"))) -> High-Value Dock Owner | P40: =IF(O40="Premier Dock Owner","A",IF(O40="High-Value Dock Owner","B","C")) -> B | Q40: =IF(Table13[[#This Row],[target_priority]]="A","Direct Outreach",IF(Table13[[#This Row],[target_priority]]="B","Personalized Mail Campaign","Low Priority / Monitor")) -> Personalized Mail Campaign | R40: Recently Sold
A41: 507 Redbud Ct | C41: Lake Ozark | D41: MO | E41: 65049 | F41: 5 | G41: 7 | H41: 3950 | I41: 2320000 | J41: =Table13[[#This Row],[property_value]]/Table13[[#This Row],[sqft]] -> 587.34177 | L41: Dock | M41: =IF(L41="Dock",50,IF(L41="Waterfront",40,IF(L41="Access",20,0)))+IF(I41>5000000,30,IF(I41>2000000,25,IF(I41>1000000,20,10)))+IF(H41>6000,15,IF(H41>4000,10,5))+IF(F41>=6,10,IF(F41>=4,5,0)) -> 85 | N41: =_xlfn.RANK.EQ(M41,$M$11:$M$68,0) -> 24 | O41: =IF(M41>=100,"Premier Dock Owner",IF(M41>=85,"High-Value Dock Owner",IF(M41>=65,"Waterfront / Access Prospect","Lower Priority"))) -> High-Value Dock Owner | P41: =IF(O41="Premier Dock Owner","A",IF(O41="High-Value Dock Owner","B","C")) -> B | Q41: =IF(Table13[[#This Row],[target_priority]]="A","Direct Outreach",IF(Table13[[#This Row],[target_priority]]="B","Personalized Mail Campaign","Low Priority / Monitor")) -> Personalized Mail Campaign | R41: Active Listing
A42: 1258 Bonard Ln | C42: Osage Beach | D42: MO | E42: 65065 | F42: 6 | G42: 6 | H42: 3903 | I42: 1599000 | J42: =Table13[[#This Row],[property_value]]/Table13[[#This Row],[sqft]] -> 409.68486 | L42: Dock | M42: =IF(L42="Dock",50,IF(L42="Waterfront",40,IF(L42="Access",20,0)))+IF(I42>5000000,30,IF(I42>2000000,25,IF(I42>1000000,20,10)))+IF(H42>6000,15,IF(H42>4000,10,5))+IF(F42>=6,10,IF(F42>=4,5,0)) -> 85 | N42: =_xlfn.RANK.EQ(M42,$M$11:$M$68,0) -> 24 | O42: =IF(M42>=100,"Premier Dock Owner",IF(M42>=85,"High-Value Dock Owner",IF(M42>=65,"Waterfront / Access Prospect","Lower Priority"))) -> High-Value Dock Owner | P42: =IF(O42="Premier Dock Owner","A",IF(O42="High-Value Dock Owner","B","C")) -> B | Q42: =IF(Table13[[#This Row],[target_priority]]="A","Direct Outreach",IF(Table13[[#This Row],[target_priority]]="B","Personalized Mail Campaign","Low Priority / Monitor")) -> Personalized Mail Campaign | R42: Active Listing
...
